Workbook
Name CostOfEquity: WACC!$C$16
Name DCF_ValuePerShare: DCF!$E$83
Name EV_DCF: DCF!$E$73
Name ImpliedMargin: Reverse_DCF!$C$6
Name ModelStatus: Checks!$D$3
Name PeerValuePerShare: Comps!$H$33
Name Recommendation: DCF!$E$114
Name RevenueMode: Inputs!$C$72
Name Scenario: Inputs!$C$53
Name SharePrice: Inputs!$C$27
Name TargetPrice: DCF!$E$109
Name TerminalGrowth: Drivers!$H$91
Name WACC_used: WACC!$C$34

Sheet Cover
D7: =Inputs!$C$6 -> Example Company ASA
D8: DCF Valuation Model
D10: =Inputs!$C$7&" | "&Inputs!$C$8&" | "&Inputs!$C$9&" | figures in "&Inputs!$C$11 -> EXMPL | Oslo Børs | Consumer services | figures in NOKm
D12: =DCF!$E$114&" – target price NOK "&TEXT(DCF!$E$109,"0")&" ("&TEXT(DCF!$E$110,"+0%;-0%")&" upside) | scenario: "&Inputs!$C$53 -> BUY – target price NOK 146 (+20% upside) | scenario: Base
D13: ="Model status: "&Checks!$D$3 -> Model status: ALL CHECKS OK
D14: All company data in this file is FICTIONAL example data – replace the blue inputs with your case data.
D15: =Inputs!$C$12 -> [Case team name]
D17: Model map (click a sheet name to open it) | H17: Colour legend
D18: Guide | E18: How to use | F18: Step-by-step guide, method notes and mapping of Pareto case data | H18: 1,234 | I18: Hard-coded input (blue)
D20: INPUTS | E20: Everything you type lives here. Blue figures are hard-coded inputs; yellow cells are forecast assumptions. | H20: 1,234 | I20: Forecast assumption / switch (blue on yellow)
D21: Inputs | E21: General inputs | F21: Company info, timeline, market data, net debt bridge and valuation settings | H21: 1,234 | I21: Formula (black)
D22: Hist | E22: As reported | F22: Seven years of reported income statement, balance sheet, cash flow and KPIs | H22: 1,234 | I22: Direct link to another sheet (green)
D23: Drivers | E23: Assumptions cockpit | F23: Forecast drivers per year, Bear/Base/Bull adjustments, terminal assumptions, cost structure and capital allocation | H23: 1,234 | I23: Key line / key output (light blue)
D25: CALCULATIONS | E25: The calculation engine. No inputs except known one-off items. | H25: 0.0 | I25: Integrity check – should be zero (grey italic)
D26: Model | E26: Operating model | F26: Revenue build (locations or volume x price), earnings build, investments, free cash flow and financing
D28: OUTPUT | E28: Link-only presentation of the results – what you would show in a report. | H28: Sign convention: income positive, costs negative.
D29: Output | E29: Financial statements | F29: Income statement, balance sheet (capital employed) and cash flow with integrity checks | H29: Units: NOKm unless stated; per share in NOK.
D30: Analysis | E30: Financial analysis | F30: Growth, margins, ROIC vs. WACC, leverage, per-share data and valuation multiples | H30: Historicals have grey year headers, forecasts navy.
D32: VALUATION | E32: From cost of capital to target price, cross-checked with peers. | H32: Explanations sit in the Notes column on each sheet.
D33: WACC | E33: Cost of capital | F33: CAPM with peer-based beta, cost of debt and target capital structure
D34: DCF | E34: DCF valuation | F34: FCFF, stub period and mid-year discounting, terminal value, equity bridge and target price
D35: Sensitivity | E35: Sensitivity & scenarios | F35: WACC vs. growth, WACC vs. exit multiple, growth vs. margin and Bear/Base/Bull
D36: Comps | E36: Trading multiples | F36: Peer group statistics and implied value per share
D37: Football | E37: Football field | F37: Valuation summary across all methods, with chart
D39: MARKET VIEW | E39: What the share price implies, where we differ from consensus – and what would prove us wrong.
D40: Reverse_DCF | E40: Reverse DCF | F40: Market-implied EBIT margin, growth, WACC and terminal growth at today's share price
D41: Consensus | E41: Consensus vs. our estimates | F41: Consensus inputs, our estimates vs. consensus and our variant perception
D42: Thesis | E42: Thesis tracker | F42: Scenario stories, signposts and kill criteria with a live status
D44: SUMMARY | E44: One-page overview, numbers for the pitch deck and the model health check.
D45: Dashboard | E45: Dashboard | F45: Recommendation, key financials and charts on one page
D46: Deck_Feed | E46: Deck feed | F46: Numbers and text lines ready to paste into the pitch deck
D47: Checks | E47: Integrity checks | F47: All checks must be OK before the model is submitted
D50: Version 3.0 – September 2026 · data set: Example Company ASA. Recalculate fully (Ctrl+Alt+F9) after pasting new data; press F9 to refresh data tables.

Sheet Guide
B1: Guide
B3: How to use the model – 8 steps
B4: 1 | C4: Inputs: company name, ticker, first historical year, valuation date, share price, shares, and net debt from the latest quarterly report.
B5: 2 | C5: Hist: paste seven years of reported figures. Costs are negative numbers. Map Pareto's 'Model' sheet lines using the table below.
B6: 3 | C6: Check the Hist balance check and cash flow check rows (should be zero) before moving on.
B7: 4 | C7: Choose the revenue build on Inputs (1 = segments, 2 = locations). Drivers (section A): price/mix growth per segment, then either volume growth (segment mode) or like-for-like growth, net new locations and capex per new location (location mode); the variable cost ratios, cost inflation, maintenance capex, NWC and tax per year. Rows the active build does not use are greyed out.
B8: 5 | C8: Drivers (section B/D/E/F): Bear/Bull adjustments and probabilities, terminal assumptions (g, RONIC, exit multiple), the fixed and central share of costs, capital allocation (target leverage, buybacks) and the ramp-up curve for new locations.
B9: 6 | C9: WACC: update risk-free rate, equity risk premium and peer betas. Comps: paste the peer table from the case material.
B10: 7 | C10: Review Output (the balance sheet and cash flow checks must be zero), Analysis, Dashboard, Sensitivity and Football. Resolve every ERROR on Checks and be ready to explain each WARNING.
B11: 8 | C11: Set the scenario back to Base, then copy numbers from Deck_Feed into the pitch deck.
B13: How the workbook is organised
B14: • | C14: Inputs >>> (Inputs, Hist, Drivers) is the only place you type. Calculations >>> (Model) is the engine. Output >>> (Output, Analysis) presents the results link-only. Valuation >>> (WACC, DCF, Sensitivity, Comps, Football) values the company. Summary >>> (Dashboard, Deck_Feed, Checks) wraps it up.
B15: • | C15: Blue = hard-coded input, blue on yellow = forecast assumption or switch, black = formula, green = link to another sheet, light blue row = key line, grey italic = check.
B17: Method notes
B18: • | C18: FCFF is on a pre-IFRS 16 basis: lease payments are treated as operating costs (EBITDAaL). Lease liabilities are therefore NOT deducted in the equity bridge. This avoids the classic mismatch of IFRS 16 EBITDA margins in history vs. pre-IFRS 16 margins in the forecast.
B19: • | C19: Stub period: only the remaining share of the first forecast year is valued; cash flows are discounted from the valuation date (mid-year convention optional).
B20: • | C20: Terminal value uses the value-driver formula: FCFF = NOPAT x (1 – g / RONIC). This forces reinvestment consistent with growth. With RONIC = WACC, growth adds no value.
B21: • | C21: Growth is paid for: capex = maintenance capex + growth capex. Location mode: openings x capex per new location; segment mode: incremental revenue / sales-to-capital. The DCF sanity checks compare the return on new capital in the explicit period with the higher of today's ROIC and the terminal RONIC – a forecast that grows almost for free is flagged.
B22: • | C22: Location engine (revenue build 2): volume = mature-equivalent locations x volume per mature location. New locations ramp up over three years (Drivers F); volume per location grows with like-for-like growth. Fixed costs grow with inflation and the number of locations (except the central share) and rent per location grows with inflation – so openings dilute margins at first and add to them as they mature.
B23: • | C23: Operating leverage is a result, not an input: personnel and other opex are split into a fixed part (grows with cost inflation and capacity) and a variable part (% of revenue). Margin expansion therefore follows from the growth you assume.
B24: • | C24: Capital structure: the WACC uses either a target D/(D+E) or the average modelled from the forecast balance sheet. With the buyback switch on, cash above the target leverage is returned so the forecast structure stays close to the WACC assumption; a gap above 10pp is flagged.
B25: • | C25: Target price = blended fair value (DCF and peers) rolled forward 12 months at the cost of equity, less the expected dividend. Rating: BUY only if the expected total return exceeds the cost of equity by the threshold on Inputs – a fairly priced share returns Ke, not zero.
B26: • | C26: The football field shows values today (fair value marker). The 12-month target price is drawn separately because it is rolled forward at the cost of equity and is not comparable with the ranges.
B27: • | C27: Reverse_DCF solves the DCF for today's share price: the EBIT margin (exact closed form – the DCF is linear in a uniform margin shift), growth (interpolated in Sensitivity table 5, a data table), WACC and terminal growth (bisection on the closed-form DCF). Use it to say what the market prices in – and where you differ.
B28: • | C28: Consensus: type the latest consensus (reported IFRS 16 basis) and your variant perception – topic, our view, consensus view, evidence and the catalyst that proves it. Thesis: scenario stories and kill criteria with a live status on the latest actuals.
B29: • | C29: Sensitivity tables 1-2 are live formulas. Tables 3-4 are Excel data tables – if they look stale, press F9 (File > Options > Formulas > Automatic).
B30: • | C30: Interest in the forecast is calculated on opening net debt, so the model has no circular references.
B32: Mapping Pareto case data ('Model' sheet) to Hist
C33: Revenues / Membership fees / Other | D33: Revenue – segment A/B/C (use A only if there is no split)
C34: COGS | D34: Cost of goods sold (negative)
C35: Salaries and personnel costs | D35: Personnel expenses (negative)
C36: Other expenses / Operating expenses | D36: Other operating expenses (negative)
C37: Depreciation & amortization | D37: D&A – owned assets + Depreciation – right-of-use assets (split using the lease note)
C38: Impairments | D38: Impairments and special items
C39: Net interest / Financial income + expenses | D39: Net financial items excl. leases + Interest on lease liabilities
C40: Tax expense | D40: Income tax (negative)
C41: Non-controlling interest | D41: Minority interests (negative)
C42: Installments + interests on lease liabilities / Rent payments | D42: Lease payments, total (negative)
C43: Balance sheet lines | D43: Same names on Hist – put anything else in 'Other' lines so totals match
C44: Members / FTEs / Clubs / Stores | D44: Volume KPIs and Locations per segment
...

Sheet Inputs >>>
D8: =Inputs!$C$6 -> Example Company ASA
D9: Financial Model
D12: Inputs
D14: Everything you type lives here. Blue figures are hard-coded inputs; yellow cells are forecast assumptions.
D17: Inputs | E17: General inputs | F17: Company info, timeline, market data, net debt bridge and valuation settings
D18: Hist | E18: As reported | F18: Seven years of reported income statement, balance sheet, cash flow and KPIs
D19: Drivers | E19: Assumptions cockpit | F19: Forecast drivers per year, Bear/Base/Bull adjustments, terminal assumptions, cost structure and capital allocation
D22: ← Back to cover

Sheet Inputs
B1: Inputs & settings
B2: Blue cells on a yellow background are inputs. Start here.
B4: 1. Company information | H4: Lists
B6: Company name | C6: Example Company ASA | E6: Used in all headers | H6: Bear
B7: Ticker | C7: EXMPL | H7: Base
B8: Exchange | C8: Oslo Børs | H8: Bull
B9: Sector | C9: Consumer services
B10: Reporting currency | C10: NOK
B11: Reporting unit | C11: NOKm | E11: All financial figures are in this unit
B12: Case team / analyst | C12: [Case team name]
B13: Model date | C13: 46281
B15: 2. Timeline
B17: First historical year | C17: 2019 | E17: Seven historical years: first year + 6
B18: Last actual year | C18: =$C$17+6 -> 2025
B19: First forecast year | C19: =$C$18+1 -> 2026
B20: Last explicit forecast year | C20: =$C$19+7 -> 2033 | E20: Eight explicit forecast years, then terminal value
B21: Valuation date | C21: 46281 | E21: Normally the share price date
B22: Fiscal year end, first forecast year | C22: =DATE($C$19,12,31) -> 46387 | E22: Assumes December year end
B23: Share of first forecast year remaining | C23: =MAX(0,MIN(1,($C$22-$C$21)/365)) -> 0.29041096 | E23: Only this share of the first year's FCFF is valued (stub period)
B25: 3. Market data
B27: Share price | C27: 122 | D27: NOK | E27: Source: Oslo Børs / Bloomberg – update
B28: Share price date | C28: 46281
B29: Shares outstanding | C29: 85 | D29: m | E29: Excl. treasury shares
B30: Dilutive instruments (options, RSUs) | C30: 0.6 | D30: m | E30: Treasury-stock method or face value
B31: Diluted shares | C31: =$C$29+$C$30 -> 85.6 | D31: m
B32: Market capitalisation | C32: =$C$27*$C$29 -> 10370 | D32: NOKm
B33: 52-week high | C33: 134.6 | D33: NOK
B34: 52-week low | C34: 101.2 | D34: NOK
B35: Consensus target price (optional) | C35: 135 | D35: NOK | E35: Bloomberg consensus, if provided in the case material
B37: 4. Net debt and EV bridge (latest reported balance sheet)
B39: Balance sheet date | C39: 46203 | E39: Latest quarterly report
B40: Interest-bearing debt | C40: 1420 | D40: NOKm | E40: Excl. lease liabilities
B41: Cash and cash equivalents | C41: 395 | D41: NOKm
B42: Net interest-bearing debt excl. leases | C42: =$C$40-$C$41 -> 1025 | D42: NOKm
B43: Lease liabilities (IFRS 16) | C43: 1805 | D43: NOKm | E43: Not deducted in the DCF: FCFF is after lease payments (pre-IFRS 16)
B44: Minority interests | C44: 70 | D44: NOKm | E44: Book value, or market value if available
B45: Associates and financial investments | C45: 40 | D45: NOKm | E45: Non-operating assets not captured by FCFF
B46: Pension deficit and other debt-like items | C46: 20 | D46: NOKm
B47: Other adjustments (+ adds to equity value) | C47: 0 | D47: NOKm
B48: Enterprise value at current price, excl. leases | C48: =$C$32+$C$42+$C$44-$C$45+$C$46-$C$47 -> 11445 | D48: NOKm
...

Sheet Hist
B1: Historical financials | K1: =Inputs!$C$6&" | Scenario: "&Inputs!$C$53 -> Example Company ASA | Scenario: Base
B2: Paste reported figures into the blue cells (costs as negative numbers). Subtotals and ratios are calculated.
E3: =Inputs!$C$17+0 -> 2019 | F3: =Inputs!$C$17+1 -> 2020 | G3: =Inputs!$C$17+2 -> 2021 | H3: =Inputs!$C$17+3 -> 2022 | I3: =Inputs!$C$17+4 -> 2023 | J3: =Inputs!$C$17+5 -> 2024 | K3: =Inputs!$C$17+6 -> 2025
E4: Historicals
B5: ="("&Inputs!$C$11&")" -> (NOKm) | E5: =E3&"A" -> 2019A | F5: =F3&"A" -> 2020A | G5: =G3&"A" -> 2021A | H5: =H3&"A" -> 2022A | I5: =I3&"A" -> 2023A | J5: =J3&"A" -> 2024A | K5: =K3&"A" -> 2025A
B7: Income statement
B9: ="Revenue – "&Inputs!$C$73 -> Revenue – Norway | C9: NOKm | E9: 1950 | F9: 1790 | G9: 1880 | H9: 2150 | I9: 2340 | J9: 2505 | K9: 2690
B10: ="Revenue – "&Inputs!$C$74 -> Revenue – Sweden | C10: NOKm | E10: 1240 | F10: 1130 | G10: 1190 | H10: 1400 | I10: 1545 | J10: 1665 | K10: 1785
B11: ="Revenue – "&Inputs!$C$75 -> Revenue – Denmark & Finland | C11: NOKm | E11: 600 | F11: 548 | G11: 598 | H11: 712 | I11: 802 | J11: 875 | K11: 958
B12: Total revenue | C12: NOKm | E12: =SUM(E9:E11) -> 3790 | F12: =SUM(F9:F11) -> 3468 | G12: =SUM(G9:G11) -> 3668 | H12: =SUM(H9:H11) -> 4262 | I12: =SUM(I9:I11) -> 4687 | J12: =SUM(J9:J11) -> 5045 | K12: =SUM(K9:K11) -> 5433
B13: Cost of goods sold | C13: NOKm | E13: -1383.3 | F13: -1310.9 | G13: -1364.5 | H13: -1623.8 | I13: -1762.3 | J13: -1866.7 | K13: -1988.5
B14: Gross profit | C14: NOKm | E14: =E12+E13 -> 2406.7 | F14: =F12+F13 -> 2157.1 | G14: =G12+G13 -> 2303.5 | H14: =H12+H13 -> 2638.2 | I14: =I12+I13 -> 2924.7 | J14: =J12+J13 -> 3178.3 | K14: =K12+K13 -> 3444.5
B15: Personnel expenses | C15: NOKm | E15: -871.7 | F15: -853.1 | G15: -873 | H15: -976 | I15: -1049.9 | J15: -1114.9 | K15: -1184.4
B16: Other operating expenses | C16: NOKm | E16: -485.1 | F16: -468.2 | G16: -480.5 | H16: -537 | I16: -576.5 | J16: -610.4 | K16: -646.5
B17: EBITDA (reported, IFRS 16) | C17: NOKm | E17: =E14+E15+E16 -> 1049.9 | F17: =F14+F15+F16 -> 835.8 | G17: =G14+G15+G16 -> 950 | H17: =H14+H15+H16 -> 1125.2 | I17: =I14+I15+I16 -> 1298.3 | J17: =J14+J15+J16 -> 1453 | K17: =K14+K15+K16 -> 1613.6
B18: D&A – owned assets | C18: NOKm | E18: -174.3 | F18: -176.9 | G18: -179.7 | H18: -196.1 | I18: -210.9 | J18: -227 | K18: -239.1
B19: Depreciation – right-of-use assets | C19: NOKm | E19: -254.7 | F19: -258 | G19: -261.2 | H19: -279.6 | I19: -300 | J19: -318.9 | K19: -339
B20: Impairments and special items | C20: NOKm | E20: 0 | F20: -45 | G20: 0 | H20: 0 | I20: -20 | J20: 0 | K20: 0
B21: EBIT (reported) | C21: NOKm | E21: =E17+E18+E19+E20 -> 620.9 | F21: =F17+F18+F19+F20 -> 355.9 | G21: =G17+G18+G19+G20 -> 509.1 | H21: =H17+H18+H19+H20 -> 649.5 | I21: =I17+I18+I19+I20 -> 767.4 | J21: =J17+J18+J19+J20 -> 907.1 | K21: =K17+K18+K19+K20 -> 1035.5
B22: Net financial items excl. leases | C22: NOKm | E22: -60.3 | F22: -49.2 | G22: -44.2 | H22: -55 | I22: -84 | J22: -82.1 | K22: -80.4
B23: Interest on lease liabilities | C23: NOKm | E23: -63.7 | F23: -64.5 | G23: -65.3 | H23: -69.9 | I23: -75 | J23: -79.7 | K23: -84.8
B24: Profit before tax | C24: NOKm | E24: =E21+E22+E23 -> 496.9 | F24: =F21+F22+F23 -> 242.2 | G24: =G21+G22+G23 -> 399.6 | H24: =H21+H22+H23 -> 524.6 | I24: =I21+I22+I23 -> 608.4 | J24: =J21+J22+J23 -> 745.3 | K24: =K21+K22+K23 -> 870.3
B25: Income tax | C25: NOKm | E25: -114.3 | F25: -61.3 | G25: -87.9 | H25: -115.4 | I25: -133.8 | J25: -164 | K25: -191.5
B26: Net profit | C26: NOKm | E26: =E24+E25 -> 382.6 | F26: =F24+F25 -> 180.9 | G26: =G24+G25 -> 311.7 | H26: =H24+H25 -> 409.2 | I26: =I24+I25 -> 474.6 | J26: =J24+J25 -> 581.3 | K26: =K24+K25 -> 678.8
B27: Minority interests | C27: NOKm | E27: -3.8 | F27: -1.8 | G27: -3.1 | H27: -4.1 | I27: -4.7 | J27: -5.8 | K27: -6.8
B28: Net profit to shareholders | C28: NOKm | E28: =E26+E27 -> 378.8 | F28: =F26+F27 -> 179.1 | G28: =G26+G27 -> 308.6 | H28: =H26+H27 -> 405.1 | I28: =I26+I27 -> 469.9 | J28: =J26+J27 -> 575.5 | K28: =K26+K27 -> 672
B30: IFRS 16 adjustment and adjusted earnings
B32: Lease payments, total (from cash flow statement) | C32: NOKm | E32: -318.4 | F32: -322.5 | G32: -326.5 | H32: -349.5 | I32: -375 | J32: -398.6 | K32: -423.8 | V32: Principal + interest. Enter as a negative number
B33: EBITDAaL – EBITDA after leases (pre-IFRS 16) | C33: NOKm | E33: =E17+E32 -> 731.5 | F33: =F17+F32 -> 513.3 | G33: =G17+G32 -> 623.5 | H33: =H17+H32 -> 775.7 | I33: =I17+I32 -> 923.3 | J33: =J17+J32 -> 1054.4 | K33: =K17+K32 -> 1189.8
B34: EBIT adj. (pre-IFRS 16, excl. special items) | C34: NOKm | E34: =E33+E18 -> 557.2 | F34: =F33+F18 -> 336.4 | G34: =G33+G18 -> 443.8 | H34: =H33+H18 -> 579.6 | I34: =I33+I18 -> 712.4 | J34: =J33+J18 -> 827.4 | K34: =K33+K18 -> 950.7
B36: Balance sheet
B38: Goodwill | C38: NOKm | E38: 1800 | F38: 1800 | G38: 1800 | H38: 2400 | I38: 2400 | J38: 2730 | K38: 2730
B39: Other intangible assets | C39: NOKm | E39: 230 | F39: 230 | G39: 230 | H39: 370 | I39: 370 | J39: 460 | K39: 460
B40: Property, plant and equipment | C40: NOKm | E40: 842.8 | F40: 790.7 | G40: 772.4 | H40: 875 | I40: 917.2 | J40: 977.5 | K40: 1010.1
B41: Right-of-use assets | C41: NOKm | E41: 1267.3 | F41: 1284.5 | G41: 1301.3 | H41: 1397.9 | I41: 1505 | J41: 1604.1 | K41: 1710
B42: Other non-current assets | C42: NOKm | E42: 55 | F42: 55 | G42: 55 | H42: 55 | I42: 55 | J42: 55 | K42: 55
B43: Inventories | C43: NOKm | E43: 151.6 | F43: 138.7 | G43: 146.7 | H43: 170.5 | I43: 187.5 | J43: 201.8 | K43: 217.3
B44: Trade receivables | C44: NOKm | E44: 132.7 | F44: 121.4 | G44: 128.4 | H44: 149.2 | I44: 164 | J44: 176.6 | K44: 190.2
B45: Other current assets | C45: NOKm | E45: 75.8 | F45: 69.4 | G45: 73.4 | H45: 85.2 | I45: 93.7 | J45: 100.9 | K45: 108.7
B46: Cash and cash equivalents | C46: NOKm | E46: 451.5 | F46: 787.4 | G46: 1092.5 | H46: 451.2 | I46: 521.4 | J46: 243 | K46: 461.4
...

Sheet Drivers
B1: Forecast drivers & scenarios | T1: =Inputs!$C$6&" | Scenario: "&Inputs!$C$53 -> Example Company ASA | Scenario: Base
B2: Base case per year (A), scenario adjustments (B), terminal value (D), cost structure and capital allocation (E), ramp-up of new locations (F). The model reads C–F.
E3: =Inputs!$C$17+0 -> 2019 | F3: =Inputs!$C$17+1 -> 2020 | G3: =Inputs!$C$17+2 -> 2021 | H3: =Inputs!$C$17+3 -> 2022 | I3: =Inputs!$C$17+4 -> 2023 | J3: =Inputs!$C$17+5 -> 2024 | K3: =Inputs!$C$17+6 -> 2025 | L3: =Inputs!$C$19+0 -> 2026 | M3: =Inputs!$C$19+1 -> 2027 | N3: =Inputs!$C$19+2 -> 2028 | O3: =Inputs!$C$19+3 -> 2029 | P3: =Inputs!$C$19+4 -> 2030 | Q3: =Inputs!$C$19+5 -> 2031 | R3: =Inputs!$C$19+6 -> 2032 | S3: =Inputs!$C$19+7 -> 2033
E4: Historicals | L4: Explicit forecast
B5: ="("&Inputs!$C$11&")" -> (NOKm) | E5: =E3&"A" -> 2019A | F5: =F3&"A" -> 2020A | G5: =G3&"A" -> 2021A | H5: =H3&"A" -> 2022A | I5: =I3&"A" -> 2023A | J5: =J3&"A" -> 2024A | K5: =K3&"A" -> 2025A | L5: =L3&"E" -> 2026E | M5: =M3&"E" -> 2027E | N5: =N3&"E" -> 2028E | O5: =O3&"E" -> 2029E | P5: =P3&"E" -> 2030E | Q5: =Q3&"E" -> 2031E | R5: =R3&"E" -> 2032E | S5: =S3&"E" -> 2033E | T5: Hist. avg (3y) | V5: Notes
B7: Active scenario | E7: =Inputs!$C$53 -> Base | G7: ="Revenue build: "&IF(Inputs!$C$72=2,"locations (like-for-like + new locations)","segments (volume x price/mix)")&" – greyed-out rows are not used (switch on Inputs)" -> Revenue build: locations (like-for-like + new locations) – greyed-out rows are not used (switch on Inputs)
B8: Scenario index (1 = Bear, 2 = Base, 3 = Bull) | E8: =Inputs!$C$54 -> 2
B10: A. Base case drivers – enter forecast assumptions in the blue cells (history shown for reference)
B12: ="Volume growth – "&Inputs!$C$73&" (segment mode)" -> Volume growth – Norway (segment mode) | C12: % | F12: =Hist!F92 -> -0.063333333 | G12: =Hist!G92 -> 0.028469751 | H12: =Hist!H92 -> 0.093425606 | I12: =Hist!I92 -> 0.041139241 | J12: =Hist!J92 -> 0.024316109 | K12: =Hist!K92 -> 0.029673591 | L12: 0.026 | M12: 0.024 | N12: 0.022 | O12: 0.02 | P12: 0.018 | Q12: 0.016 | R12: 0.014 | S12: 0.012 | T12: =IFERROR(AVERAGE(I12:K12),"") -> 0.031709647 | V12: Segment mode only (greyed out in location mode): total volume growth per segment
B13: ="Price/mix growth – "&Inputs!$C$73&"" -> Price/mix growth – Norway | C13: % | F13: =Hist!F95 -> -0.019983575 | G13: =Hist!G95 -> 0.021205853 | H13: =Hist!H95 -> 0.045902909 | I13: =Hist!I95 -> 0.045366509 | J13: =Hist!J95 -> 0.045100053 | K13: =Hist!K95 -> 0.042905543 | L13: 0.034 | M13: 0.03 | N13: 0.028 | O13: 0.026 | P13: 0.025 | Q13: 0.024 | R13: 0.023 | S13: 0.022 | T13: =IFERROR(AVERAGE(I13:K13),"") -> 0.044457368
B14: ="Volume growth – "&Inputs!$C$74&" (segment mode)" -> Volume growth – Sweden (segment mode) | C14: % | F14: =Hist!F93 -> -0.070175439 | G14: =Hist!G93 -> 0.033018868 | H14: =Hist!H93 -> 0.12785388 | I14: =Hist!I93 -> 0.048582996 | J14: =Hist!J93 -> 0.030888031 | K14: =Hist!K93 -> 0.026217228 | L14: 0.03 | M14: 0.028 | N14: 0.026 | O14: 0.023 | P14: 0.02 | Q14: 0.018 | R14: 0.015 | S14: 0.013 | T14: =IFERROR(AVERAGE(I14:K14),"") -> 0.035229418
B15: ="Price/mix growth – "&Inputs!$C$74&"" -> Price/mix growth – Sweden | C15: % | F15: =Hist!F96 -> -0.019933049 | G15: =Hist!G96 -> 0.019436699 | H15: =Hist!H96 -> 0.043105501 | I15: =Hist!I96 -> 0.052440706 | J15: =Hist!J96 -> 0.045380168 | K15: =Hist!K96 -> 0.04468337 | L15: 0.032 | M15: 0.03 | N15: 0.028 | O15: 0.026 | P15: 0.025 | Q15: 0.024 | R15: 0.023 | S15: 0.022 | T15: =IFERROR(AVERAGE(I15:K15),"") -> 0.047501415
B16: ="Volume growth – "&Inputs!$C$75&" (segment mode)" -> Volume growth – Denmark & Finland (segment mode) | C16: % | F16: =Hist!F94 -> -0.06779661 | G16: =Hist!G94 -> 0.063636364 | H16: =Hist!H94 -> 0.12820513 | I16: =Hist!I94 -> 0.083333333 | J16: =Hist!J94 -> 0.048951049 | K16: =Hist!K94 -> 0.053333333 | L16: 0.055 | M16: 0.05 | N16: 0.045 | O16: 0.04 | P16: 0.035 | Q16: 0.03 | R16: 0.025 | S16: 0.02 | T16: =IFERROR(AVERAGE(I16:K16),"") -> 0.061872572
B17: ="Price/mix growth – "&Inputs!$C$75&"" -> Price/mix growth – Denmark & Finland | C17: % | F17: =Hist!F97 -> -0.020242424 | G17: =Hist!G97 -> 0.02595296 | H17: =Hist!H97 -> 0.055335968 | I17: =Hist!I97 -> 0.039757995 | J17: =Hist!J97 -> 0.040108063 | K17: =Hist!K97 -> 0.039421338 | L17: 0.03 | M17: 0.028 | N17: 0.027 | O17: 0.026 | P17: 0.025 | Q17: 0.024 | R17: 0.023 | S17: 0.022 | T17: =IFERROR(AVERAGE(I17:K17),"") -> 0.039762465
B18: ="Like-for-like growth per location – "&Inputs!$C$73&" (location mode)" -> Like-for-like growth per location – Norway (location mode) | C18: % | F18: =Hist!F107 -> -0.074618474 | G18: =Hist!G107 -> 0.0042704626 | H18: =Hist!H107 -> 0.056149733 | I18: =Hist!I107 -> 0.029441047 | J18: =Hist!J107 -> 0.0018036675 | K18: =Hist!K107 -> -0.0031883326 | L18: 0.008 | M18: 0.007 | N18: 0.006 | O18: 0.005 | P18: 0.004 | Q18: 0.003 | R18: 0.003 | S18: 0.003 | T18: =IFERROR(AVERAGE(I18:K18),"") -> 0.0093521272 | V18: Location mode: growth in volume per MATURE location. History: growth in volume per location
B19: ="Like-for-like growth per location – "&Inputs!$C$74&" (location mode)" -> Like-for-like growth per location – Sweden (location mode) | C19: % | F19: =Hist!F108 -> -0.083651157 | G19: =Hist!G108 -> 0.018261456 | H19: =Hist!H108 -> 0.081503722 | I19: =Hist!I108 -> 0.020620783 | J19: =Hist!J108 -> 0.017323715 | K19: =Hist!K108 -> 0.012889732 | L19: 0.01 | M19: 0.009 | N19: 0.008 | O19: 0.007 | P19: 0.006 | Q19: 0.005 | R19: 0.004 | S19: 0.003 | T19: =IFERROR(AVERAGE(I19:K19),"") -> 0.016944743
B20: ="Like-for-like growth per location – "&Inputs!$C$75&" (location mode)" -> Like-for-like growth per location – Denmark & Finland (location mode) | C20: % | F20: =Hist!F109 -> -0.06779661 | G20: =Hist!G109 -> 0.031404959 | H20: =Hist!H109 -> -0.069230769 | I20: =Hist!I109 -> 0.031746032 | J20: =Hist!J109 -> 0.0012714558 | K20: =Hist!K109 -> 0.0075362319 | L20: 0.015 | M20: 0.014 | N20: 0.012 | O20: 0.01 | P20: 0.009 | Q20: 0.008 | R20: 0.006 | S20: 0.005 | T20: =IFERROR(AVERAGE(I20:K20),"") -> 0.013517906
B21: ="Net new locations – "&Inputs!$C$73&" (location mode)" -> Net new locations – Norway (location mode) | C21: # | F21: =Hist!F101 -> 1 | G21: =Hist!G101 -> 2 | H21: =Hist!H101 -> 3 | I21: =Hist!I101 -> 1 | J21: =Hist!J101 -> 2 | K21: =Hist!K101 -> 3 | L21: 2 | M21: 2 | N21: 2 | O21: 2 | P21: 2 | Q21: 1 | R21: 1 | S21: 1 | T21: =IFERROR(AVERAGE(I21:K21),"") -> 2 | V21: Location mode: openings minus closures. New locations ramp up over three years (section F)
B22: ="Net new locations – "&Inputs!$C$74&" (location mode)" -> Net new locations – Sweden (location mode) | C22: # | F22: =Hist!F102 -> 1 | G22: =Hist!G102 -> 1 | H22: =Hist!H102 -> 3 | I22: =Hist!I102 -> 2 | J22: =Hist!J102 -> 1 | K22: =Hist!K102 -> 1 | L22: 2 | M22: 2 | N22: 2 | O22: 2 | P22: 1 | Q22: 1 | R22: 1 | S22: 1 | T22: =IFERROR(AVERAGE(I22:K22),"") -> 1.3333333
B23: ="Net new locations – "&Inputs!$C$75&" (location mode)" -> Net new locations – Denmark & Finland (location mode) | C23: # | F23: =Hist!F103 -> 0 | G23: =Hist!G103 -> 1 | H23: =Hist!H103 -> 7 | I23: =Hist!I103 -> 2 | J23: =Hist!J103 -> 2 | K23: =Hist!K103 -> 2 | L23: 3 | M23: 3 | N23: 3 | O23: 2 | P23: 2 | Q23: 2 | R23: 1 | S23: 1 | T23: =IFERROR(AVERAGE(I23:K23),"") -> 2
B24: COGS in % of revenue | C24: % | E24: =Hist!E111 -> 0.36498681 | F24: =Hist!F111 -> 0.37799885 | G24: =Hist!G111 -> 0.37200109 | H24: =Hist!H111 -> 0.38099484 | I24: =Hist!I111 -> 0.37599744 | J24: =Hist!J111 -> 0.37000991 | K24: =Hist!K111 -> 0.36600405 | L24: 0.366 | M24: 0.366 | N24: 0.366 | O24: 0.366 | P24: 0.366 | Q24: 0.366 | R24: 0.366 | S24: 0.366 | T24: =IFERROR(AVERAGE(I24:K24),"") -> 0.37067047
B25: Personnel expenses – variable part, in % of revenue | C25: % | E25: =Hist!E112 -> 0.23 | F25: =Hist!F112 -> 0.24599193 | G25: =Hist!G112 -> 0.23800436 | H25: =Hist!H112 -> 0.22900047 | I25: =Hist!I112 -> 0.22400256 | J25: =Hist!J112 -> 0.22099108 | K25: =Hist!K112 -> 0.2180011 | L25: 0.0872 | M25: 0.0872 | N25: 0.0872 | O25: 0.0872 | P25: 0.0872 | Q25: 0.0872 | R25: 0.0872 | S25: 0.0872 | T25: =IFERROR(AVERAGE(I25:K25),"") -> 0.22099825 | V25: History shows the TOTAL ratio. Only this part scales with revenue – the fixed part (section E) grows with inflation and locations
B26: Other opex – variable part, in % of revenue | C26: % | E26: =Hist!E113 -> 0.12799472 | F26: =Hist!F113 -> 0.13500577 | G26: =Hist!G113 -> 0.13099782 | H26: =Hist!H113 -> 0.12599718 | I26: =Hist!I113 -> 0.12299979 | J26: =Hist!J113 -> 0.12099108 | K26: =Hist!K113 -> 0.11899503 | L26: 0.0595 | M26: 0.0595 | N26: 0.0595 | O26: 0.0595 | P26: 0.0595 | Q26: 0.0595 | R26: 0.0595 | S26: 0.0595 | T26: =IFERROR(AVERAGE(I26:K26),"") -> 0.1209953 | V26: History shows the TOTAL ratio – see personnel expenses
B27: Cost inflation on the fixed cost base and rent | C27: % | L27: 0.03 | M27: 0.027 | N27: 0.025 | O27: 0.025 | P27: 0.025 | Q27: 0.025 | R27: 0.025 | S27: 0.025 | T27: =IFERROR(AVERAGE(I27:K27),"") | V27: Wage and price inflation on the fixed cost base – and on rent per location in location mode
B28: Real growth in the fixed cost base (segment mode) | C28: % | L28: 0.015 | M28: 0.015 | N28: 0.015 | O28: 0.015 | P28: 0.015 | Q28: 0.015 | R28: 0.015 | S28: 0.015 | T28: =IFERROR(AVERAGE(I28:K28),"") | V28: Segment mode only. In location mode the fixed cost base grows with the number of locations (section C)
B29: Lease payments in % of revenue (IFRS 16, segment mode) | C29: % | E29: =Hist!E115 -> 0.084010554 | F29: =Hist!F115 -> 0.09299308 | G29: =Hist!G115 -> 0.089013086 | H29: =Hist!H115 -> 0.082003754 | I29: =Hist!I115 -> 0.080008534 | J29: =Hist!J115 -> 0.07900892 | K29: =Hist!K115 -> 0.078004786 | L29: 0.078 | M29: 0.078 | N29: 0.077 | O29: 0.077 | P29: 0.077 | Q29: 0.077 | R29: 0.077 | S29: 0.077 | T29: =IFERROR(AVERAGE(I29:K29),"") -> 0.079007413 | V29: Segment mode only. In location mode rent per location grows with cost inflation (Model)
B30: D&A (owned assets) in % of revenue | C30: % | E30: =Hist!E117 -> 0.045989446 | F30: =Hist!F117 -> 0.051009227 | G30: =Hist!G117 -> 0.048991276 | H30: =Hist!H117 -> 0.046011262 | I30: =Hist!I117 -> 0.0449968 | J30: =Hist!J117 -> 0.044995045 | K30: =Hist!K117 -> 0.044008835 | L30: 0.044 | M30: 0.044 | N30: 0.044 | O30: 0.044 | P30: 0.044 | Q30: 0.044 | R30: 0.044 | S30: 0.044 | T30: =IFERROR(AVERAGE(I30:K30),"") -> 0.044666893
B31: Maintenance capex in % of revenue | C31: % | E31: =Hist!E117 -> 0.045989446 | F31: =Hist!F117 -> 0.051009227 | G31: =Hist!G117 -> 0.048991276 | H31: =Hist!H117 -> 0.046011262 | I31: =Hist!I117 -> 0.0449968 | J31: =Hist!J117 -> 0.044995045 | K31: =Hist!K117 -> 0.044008835 | L31: 0.05 | M31: 0.05 | N31: 0.05 | O31: 0.05 | P31: 0.05 | Q31: 0.05 | R31: 0.05 | S31: 0.05 | T31: =IFERROR(AVERAGE(I31:K31),"") -> 0.044666893 | V31: History shows D&A in % of revenue. Maintenance and refurbishment ≈ the historical capex/D&A ratio (~1.14x)
B32: Sales-to-capital for growth capex (segment mode) | C32: x | F32: =Hist!F121 -> n.m. | G32: =Hist!G121 -> n.m. | H32: =Hist!H121 -> 13.943662 | I32: =Hist!I121 -> 10.07109 | J32: =Hist!J121 -> 11.815182 | K32: =Hist!K121 -> 11.90184 | L32: 2 | M32: 2 | N32: 2 | O32: 2 | P32: 2 | Q32: 2 | R32: 2 | S32: 2 | T32: =IFERROR(AVERAGE(I32:K32),"") -> 11.262704 | V32: Segment mode only. History: incremental revenue / (capex – D&A), flattered by acquired revenue. Lower = more capital-intensive
B33: Capex per new location, NOKm (location mode) | C33: NOKm | L33: 22 | M33: 22.6 | N33: 23.1 | O33: 23.7 | P33: 24.3 | Q33: 24.9 | R33: 25.5 | S33: 26.1 | T33: =IFERROR(AVERAGE(I33:K33),"") | V33: Location mode: fit-out, equipment and pre-opening costs per new location
B34: NWC in % of revenue | C34: % | E34: =Hist!E124 -> -0.06 | F34: =Hist!F124 -> -0.051989619 | G34: =Hist!G124 -> -0.055997819 | H34: =Hist!H124 -> -0.061004223 | I34: =Hist!I124 -> -0.063004054 | J34: =Hist!J124 -> -0.064003964 | K34: =Hist!K124 -> -0.064991717 | L34: -0.065 | M34: -0.065 | N34: -0.065 | O34: -0.065 | P34: -0.065 | Q34: -0.065 | R34: -0.065 | S34: -0.065 | T34: =IFERROR(AVERAGE(I34:K34),"") -> -0.063999912
B35: Tax rate | C35: % | E35: =Hist!E122 -> 0.23002616 | F35: =Hist!F122 -> 0.25309661 | G35: =Hist!G122 -> 0.21996997 | H35: =Hist!H122 -> 0.21997713 | I35: =Hist!I122 -> 0.2199211 | J35: =Hist!J122 -> 0.22004562 | K35: =Hist!K122 -> 0.22003907 | L35: 0.22 | M35: 0.22 | N35: 0.22 | O35: 0.22 | P35: 0.22 | Q35: 0.22 | R35: 0.22 | S35: 0.22 | T35: =IFERROR(AVERAGE(I35:K35),"") -> 0.22000193
B36: Dividend payout ratio | C36: % | E36: =Hist!E131 -> 0 | F36: =Hist!F131 -> 0 | G36: =Hist!G131 -> 0.68859365 | H36: =Hist!H131 -> 0.73438657 | I36: =Hist!I131 -> 0.75973611 | J36: =Hist!J131 -> 0.70894874 | K36: =Hist!K131 -> 0.68303571 | L36: 0.65 | M36: 0.7 | N36: 0.75 | O36: 0.8 | P36: 0.85 | Q36: 0.9 | R36: 0.9 | S36: 0.9 | T36: =IFERROR(AVERAGE(I36:K36),"") -> 0.71724019
B37: Interest rate on net debt (pre-tax) | C37: % | F37: =Hist!F135 -> 0.042838485 | G37: =Hist!G135 -> 0.045917307 | H37: =Hist!H135 -> 0.090534979 | I37: =Hist!I135 -> 0.07007007 | J37: =Hist!J135 -> 0.079817227 | K37: =Hist!K135 -> 0.063961814 | L37: 0.055 | M37: 0.052 | N37: 0.05 | O37: 0.05 | P37: 0.05 | Q37: 0.05 | R37: 0.05 | S37: 0.05 | T37: =IFERROR(AVERAGE(I37:K37),"") -> 0.071283037
B38: Interest rate on net cash | C38: % | L38: 0.015 | M38: 0.015 | N38: 0.015 | O38: 0.015 | P38: 0.015 | Q38: 0.015 | R38: 0.015 | S38: 0.015 | T38: =IFERROR(AVERAGE(I38:K38),"")
B39: Interest share of lease payments | C39: % | E39: =Hist!E133 -> 0.20006281 | F39: =Hist!F133 -> 0.2 | G39: =Hist!G133 -> 0.2 | H39: =Hist!H133 -> 0.2 | I39: =Hist!I133 -> 0.2 | J39: =Hist!J133 -> 0.19994982 | K39: =Hist!K133 -> 0.20009438 | L39: 0.2 | M39: 0.2 | N39: 0.2 | O39: 0.2 | P39: 0.2 | Q39: 0.2 | R39: 0.2 | S39: 0.2 | T39: =IFERROR(AVERAGE(I39:K39),"") -> 0.20001474
B40: Minority share of net profit | C40: % | E40: =Hist!E134 -> 0.0099320439 | F40: =Hist!F134 -> 0.0099502488 | G40: =Hist!G134 -> 0.0099454604 | H40: =Hist!H134 -> 0.01001955 | I40: =Hist!I134 -> 0.0099030763 | J40: =Hist!J134 -> 0.0099776363 | K40: =Hist!K134 -> 0.010017678 | L40: 0.01 | M40: 0.01 | N40: 0.01 | O40: 0.01 | P40: 0.01 | Q40: 0.01 | R40: 0.01 | S40: 0.01 | T40: =IFERROR(AVERAGE(I40:K40),"") -> 0.0099661303
B42: B. Scenario adjustments – added to every forecast year of the base case
B43: Driver | E43: Bear | F43: Base | G43: Bull | H43: Active | J43: Comment
B44: Volume / like-for-like growth, all segments (pp p.a.) | E44: -0.015 | F44: 0 | G44: 0.01 | H44: =CHOOSE(Inputs!$C$54,E44,F44,G44) -> 0 | J44: Weaker customer intake / churn in Bear
...

Sheet Calculations >>>
D8: =Inputs!$C$6 -> Example Company ASA
D9: Financial Model
D12: Calculations
D14: The calculation engine. No inputs except known one-off items.
D17: Model | E17: Operating model | F17: Revenue build (locations or volume x price), earnings build, investments, free cash flow and financing
D20: ← Back to cover

Sheet Model
B1: Operating Model – Calculations | T1: =Inputs!$C$6&" | Scenario: "&Inputs!$C$53 -> Example Company ASA | Scenario: Base
B2: Calculation engine: history is linked from Hist, forecasts are driven by the live drivers on Drivers. Results are presented on Output.
E3: =Inputs!$C$17+0 -> 2019 | F3: =Inputs!$C$17+1 -> 2020 | G3: =Inputs!$C$17+2 -> 2021 | H3: =Inputs!$C$17+3 -> 2022 | I3: =Inputs!$C$17+4 -> 2023 | J3: =Inputs!$C$17+5 -> 2024 | K3: =Inputs!$C$17+6 -> 2025 | L3: =Inputs!$C$19+0 -> 2026 | M3: =Inputs!$C$19+1 -> 2027 | N3: =Inputs!$C$19+2 -> 2028 | O3: =Inputs!$C$19+3 -> 2029 | P3: =Inputs!$C$19+4 -> 2030 | Q3: =Inputs!$C$19+5 -> 2031 | R3: =Inputs!$C$19+6 -> 2032 | S3: =Inputs!$C$19+7 -> 2033
E4: Historicals | L4: Explicit forecast
B5: ="("&Inputs!$C$11&")" -> (NOKm) | E5: =E3&"A" -> 2019A | F5: =F3&"A" -> 2020A | G5: =G3&"A" -> 2021A | H5: =H3&"A" -> 2022A | I5: =I3&"A" -> 2023A | J5: =J3&"A" -> 2024A | K5: =K3&"A" -> 2025A | L5: =L3&"E" -> 2026E | M5: =M3&"E" -> 2027E | N5: =N3&"E" -> 2028E | O5: =O3&"E" -> 2029E | P5: =P3&"E" -> 2030E | Q5: =Q3&"E" -> 2031E | R5: =R3&"E" -> 2032E | S5: =S3&"E" -> 2033E | V5: Notes
B7: 1. Revenue build – locations x volume per location x price/mix, per segment
B9: =Inputs!$C$73 -> Norway
B10: Locations (end of year) | C10: # | E10: =Hist!E77 -> 82 | F10: =Hist!F77 -> 83 | G10: =Hist!G77 -> 85 | H10: =Hist!H77 -> 88 | I10: =Hist!I77 -> 89 | J10: =Hist!J77 -> 91 | K10: =Hist!K77 -> 94 | L10: =K10+L11 -> 96 | M10: =L10+M11 -> 98 | N10: =M10+N11 -> 100 | O10: =N10+O11 -> 102 | P10: =O10+P11 -> 104 | Q10: =P10+Q11 -> 105 | R10: =Q10+R11 -> 106 | S10: =R10+S11 -> 107
B11: Net new locations | C11: # | F11: =F10-E10 -> 1 | G11: =G10-F10 -> 2 | H11: =H10-G10 -> 3 | I11: =I10-H10 -> 1 | J11: =J10-I10 -> 2 | K11: =K10-J10 -> 3 | L11: =Drivers!L67 -> 2 | M11: =Drivers!M67 -> 2 | N11: =Drivers!N67 -> 2 | O11: =Drivers!O67 -> 2 | P11: =Drivers!P67 -> 2 | Q11: =Drivers!Q67 -> 1 | R11: =Drivers!R67 -> 1 | S11: =Drivers!S67 -> 1
B12: Openings still ramping up (forecast openings only) | C12: # | E12: =0 -> 0 | F12: =0 -> 0 | G12: =0 -> 0 | H12: =0 -> 0 | I12: =0 -> 0 | J12: =0 -> 0 | K12: =0 -> 0 | L12: =MAX(0,L11) -> 2 | M12: =MAX(0,M11) -> 2 | N12: =MAX(0,N11) -> 2 | O12: =MAX(0,O11) -> 2 | P12: =MAX(0,P11) -> 2 | Q12: =MAX(0,Q11) -> 1 | R12: =MAX(0,R11) -> 1 | S12: =MAX(0,S11) -> 1
B13: Mature-equivalent locations | C13: # | E13: =E10 -> 82 | F13: =F10 -> 83 | G13: =G10 -> 85 | H13: =H10 -> 88 | I13: =I10 -> 89 | J13: =J10 -> 91 | K13: =K10 -> 94 | L13: =K13+MIN(0,L11)+L12*Drivers!$H$110+K12*(Drivers!$H$111-Drivers!$H$110)+J12*(Drivers!$H$112-Drivers!$H$111)+I12*(1-Drivers!$H$112) -> 94.7 | M13: =L13+MIN(0,M11)+M12*Drivers!$H$110+L12*(Drivers!$H$111-Drivers!$H$110)+K12*(Drivers!$H$112-Drivers!$H$111)+J12*(1-Drivers!$H$112) -> 96.2 | N13: =M13+MIN(0,N11)+N12*Drivers!$H$110+M12*(Drivers!$H$111-Drivers!$H$110)+L12*(Drivers!$H$112-Drivers!$H$111)+K12*(1-Drivers!$H$112) -> 98.1 | O13: =N13+MIN(0,O11)+O12*Drivers!$H$110+N12*(Drivers!$H$111-Drivers!$H$110)+M12*(Drivers!$H$112-Drivers!$H$111)+L12*(1-Drivers!$H$112) -> 100.1 | P13: =O13+MIN(0,P11)+P12*Drivers!$H$110+O12*(Drivers!$H$111-Drivers!$H$110)+N12*(Drivers!$H$112-Drivers!$H$111)+M12*(1-Drivers!$H$112) -> 102.1 | Q13: =P13+MIN(0,Q11)+Q12*Drivers!$H$110+P12*(Drivers!$H$111-Drivers!$H$110)+O12*(Drivers!$H$112-Drivers!$H$111)+N12*(1-Drivers!$H$112) -> 103.75 | R13: =Q13+MIN(0,R11)+R12*Drivers!$H$110+Q12*(Drivers!$H$111-Drivers!$H$110)+P12*(Drivers!$H$112-Drivers!$H$111)+O12*(1-Drivers!$H$112) -> 105 | S13: =R13+MIN(0,S11)+S12*Drivers!$H$110+R12*(Drivers!$H$111-Drivers!$H$110)+Q12*(Drivers!$H$112-Drivers!$H$111)+P12*(1-Drivers!$H$112) -> 106.05 | V13: Location mode: existing locations + new ones weighted by the ramp-up curve (Drivers F)
B14: ="Volume per mature location ("&Inputs!$C$76&")" -> Volume per mature location (Customers ('000)) | C14: # | E14: =IF(E10=0,0,E16/E10) -> 3.6585366 | F14: =IF(F10=0,0,F16/F10) -> 3.3855422 | G14: =IF(G10=0,0,G16/G10) -> 3.4 | H14: =IF(H10=0,0,H16/H10) -> 3.5909091 | I14: =IF(I10=0,0,I16/I10) -> 3.6966292 | J14: =IF(J10=0,0,J16/J10) -> 3.7032967 | K14: =IF(K10=0,0,K16/K10) -> 3.6914894 | L14: =K14*(1+Drivers!L64) -> 3.7210213 | M14: =L14*(1+Drivers!M64) -> 3.7470684 | N14: =M14*(1+Drivers!N64) -> 3.7695508 | O14: =N14*(1+Drivers!O64) -> 3.7883986 | P14: =O14*(1+Drivers!P64) -> 3.8035522 | Q14: =P14*(1+Drivers!Q64) -> 3.8149628 | R14: =Q14*(1+Drivers!R64) -> 3.8264077 | S14: =R14*(1+Drivers!S64) -> 3.837887 | V14: Grows with like-for-like growth (Drivers A)
B15: Like-for-like growth | C15: % | F15: =IF(E14=0,0,F14/E14-1) -> -0.074618474 | G15: =IF(F14=0,0,G14/F14-1) -> 0.0042704626 | H15: =IF(G14=0,0,H14/G14-1) -> 0.056149733 | I15: =IF(H14=0,0,I14/H14-1) -> 0.029441047 | J15: =IF(I14=0,0,J14/I14-1) -> 0.0018036675 | K15: =IF(J14=0,0,K14/J14-1) -> -0.0031883326 | L15: =IF(K14=0,0,L14/K14-1) -> 0.008 | M15: =IF(L14=0,0,M14/L14-1) -> 0.007 | ... S15: =IF(R14=0,0,S14/R14-1) -> 0.003
B16: ="Volume ("&Inputs!$C$76&")" -> Volume (Customers ('000)) | C16: # | E16: =Hist!E74 -> 300 | F16: =Hist!F74 -> 281 | G16: =Hist!G74 -> 289 | H16: =Hist!H74 -> 316 | I16: =Hist!I74 -> 329 | J16: =Hist!J74 -> 337 | K16: =Hist!K74 -> 347 | L16: =IF(Inputs!$C$72=2,L13*L14,K16*(1+Drivers!L58)) -> 352.38071 | M16: =IF(Inputs!$C$72=2,M13*M14,L16*(1+Drivers!M58)) -> 360.46798 | N16: =IF(Inputs!$C$72=2,N13*N14,M16*(1+Drivers!N58)) -> 369.79294 | O16: =IF(Inputs!$C$72=2,O13*O14,N16*(1+Drivers!O58)) -> 379.2187 | P16: =IF(Inputs!$C$72=2,P13*P14,O16*(1+Drivers!P58)) -> 388.34268 | Q16: =IF(Inputs!$C$72=2,Q13*Q14,P16*(1+Drivers!Q58)) -> 395.80239 | R16: =IF(Inputs!$C$72=2,R13*R14,Q16*(1+Drivers!R58)) -> 401.77281 | S16: =IF(Inputs!$C$72=2,S13*S14,R16*(1+Drivers!S58)) -> 407.00791 | V16: Location mode: mature-equivalent locations x volume per location. Segment mode: volume growth (Drivers A)
B17: Volume growth | C17: % | F17: =F16/E16-1 -> -0.063333333 | G17: =G16/F16-1 -> 0.028469751 | H17: =H16/G16-1 -> 0.093425606 | I17: =I16/H16-1 -> 0.041139241 | J17: =J16/I16-1 -> 0.024316109 | K17: =K16/J16-1 -> 0.029673591 | L17: =L16/K16-1 -> 0.015506383 | M17: =M16/L16-1 -> 0.02295037 | ... S17: =S16/R16-1 -> 0.01303
B18: Revenue per unit | C18: NOK '000 | E18: =IF(E16=0,0,E20/E16) -> 6.5 | F18: =IF(F16=0,0,F20/F16) -> 6.3701068 | G18: =IF(G16=0,0,G20/G16) -> 6.5051903 | H18: =IF(H16=0,0,H20/H16) -> 6.8037975 | I18: =IF(I16=0,0,I20/I16) -> 7.112462 | J18: =IF(J16=0,0,J20/J16) -> 7.4332344 | K18: =IF(K16=0,0,K20/K16) -> 7.7521614 | L18: =IF(L16=0,0,L20/L16) -> 8.0157349 | ... S18: =IF(S16=0,0,S20/S16) -> 9.5558956
B19: Price/mix growth | C19: % | F19: =(1+F21)/(1+F17)-1 -> -0.019983575 | G19: =(1+G21)/(1+G17)-1 -> 0.021205853 | H19: =(1+H21)/(1+H17)-1 -> 0.045902909 | I19: =(1+I21)/(1+I17)-1 -> 0.045366509 | J19: =(1+J21)/(1+J17)-1 -> 0.045100053 | K19: =(1+K21)/(1+K17)-1 -> 0.042905543 | L19: =(1+L21)/(1+L17)-1 -> 0.034 | M19: =(1+M21)/(1+M17)-1 -> 0.03 | ... S19: =(1+S21)/(1+S17)-1 -> 0.022
B20: Revenue | C20: NOKm | E20: =Hist!E9 -> 1950 | F20: =Hist!F9 -> 1790 | G20: =Hist!G9 -> 1880 | H20: =Hist!H9 -> 2150 | I20: =Hist!I9 -> 2340 | J20: =Hist!J9 -> 2505 | K20: =Hist!K9 -> 2690 | L20: =IF(K16=0,K20*(1+Drivers!L58),K20*L16/K16)*(1+Drivers!L59) -> 2824.5904 | M20: =IF(L16=0,L20*(1+Drivers!M58),L20*M16/L16)*(1+Drivers!M59) -> 2976.0983 | N20: =IF(M16=0,M20*(1+Drivers!N58),M20*N16/M16)*(1+Drivers!N59) -> 3138.5734 | O20: =IF(N16=0,N20*(1+Drivers!O58),N20*O16/N16)*(1+Drivers!O59) -> 3302.2564 | P20: =IF(O16=0,O20*(1+Drivers!P58),O20*P16/O16)*(1+Drivers!P59) -> 3466.2512 | Q20: =IF(P16=0,P20*(1+Drivers!Q58),P20*Q16/P16)*(1+Drivers!Q59) -> 3617.6228 | R20: =IF(Q16=0,Q20*(1+Drivers!R58),Q20*R16/Q16)*(1+Drivers!R59) -> 3756.6527 | S20: =IF(R16=0,R20*(1+Drivers!S58),R20*S16/R16)*(1+Drivers!S59) -> 3889.3251
B21: Revenue growth | C21: % | F21: =F20/E20-1 -> -0.082051282 | G21: =G20/F20-1 -> 0.05027933 | H21: =H20/G20-1 -> 0.14361702 | I21: =I20/H20-1 -> 0.088372093 | J21: =J20/I20-1 -> 0.070512821 | K21: =K20/J20-1 -> 0.073852295 | L21: =L20/K20-1 -> 0.0500336 | M21: =M20/L20-1 -> 0.053638881 | ... S21: =S20/R20-1 -> 0.03531666
B23: =Inputs!$C$74 -> Sweden
B24: Locations (end of year) | C24: # | E24: =Hist!E78 -> 68 | F24: =Hist!F78 -> 69 | G24: =Hist!G78 -> 70 | H24: =Hist!H78 -> 73 | I24: =Hist!I78 -> 75 | J24: =Hist!J78 -> 76 | K24: =Hist!K78 -> 77 | L24: =K24+L25 -> 79 | M24: =L24+M25 -> 81 | N24: =M24+N25 -> 83 | O24: =N24+O25 -> 85 | P24: =O24+P25 -> 86 | Q24: =P24+Q25 -> 87 | R24: =Q24+R25 -> 88 | S24: =R24+S25 -> 89
B25: Net new locations | C25: # | F25: =F24-E24 -> 1 | G25: =G24-F24 -> 1 | H25: =H24-G24 -> 3 | I25: =I24-H24 -> 2 | J25: =J24-I24 -> 1 | K25: =K24-J24 -> 1 | L25: =Drivers!L68 -> 2 | M25: =Drivers!M68 -> 2 | N25: =Drivers!N68 -> 2 | O25: =Drivers!O68 -> 2 | P25: =Drivers!P68 -> 1 | Q25: =Drivers!Q68 -> 1 | R25: =Drivers!R68 -> 1 | S25: =Drivers!S68 -> 1
B26: Openings still ramping up (forecast openings only) | C26: # | E26: =0 -> 0 | F26: =0 -> 0 | G26: =0 -> 0 | H26: =0 -> 0 | I26: =0 -> 0 | J26: =0 -> 0 | K26: =0 -> 0 | L26: =MAX(0,L25) -> 2 | M26: =MAX(0,M25) -> 2 | N26: =MAX(0,N25) -> 2 | O26: =MAX(0,O25) -> 2 | P26: =MAX(0,P25) -> 1 | Q26: =MAX(0,Q25) -> 1 | R26: =MAX(0,R25) -> 1 | S26: =MAX(0,S25) -> 1
B27: Mature-equivalent locations | C27: # | E27: =E24 -> 68 | F27: =F24 -> 69 | G27: =G24 -> 70 | H27: =H24 -> 73 | I27: =I24 -> 75 | J27: =J24 -> 76 | K27: =K24 -> 77 | L27: =K27+MIN(0,L25)+L26*Drivers!$H$110+K26*(Drivers!$H$111-Drivers!$H$110)+J26*(Drivers!$H$112-Drivers!$H$111)+I26*(1-Drivers!$H$112) -> 77.7 | M27: =L27+MIN(0,M25)+M26*Drivers!$H$110+L26*(Drivers!$H$111-Drivers!$H$110)+K26*(Drivers!$H$112-Drivers!$H$111)+J26*(1-Drivers!$H$112) -> 79.2 | N27: =M27+MIN(0,N25)+N26*Drivers!$H$110+M26*(Drivers!$H$111-Drivers!$H$110)+L26*(Drivers!$H$112-Drivers!$H$111)+K26*(1-Drivers!$H$112) -> 81.1 | O27: =N27+MIN(0,O25)+O26*Drivers!$H$110+N26*(Drivers!$H$111-Drivers!$H$110)+M26*(Drivers!$H$112-Drivers!$H$111)+L26*(1-Drivers!$H$112) -> 83.1 | P27: =O27+MIN(0,P25)+P26*Drivers!$H$110+O26*(Drivers!$H$111-Drivers!$H$110)+N26*(Drivers!$H$112-Drivers!$H$111)+M26*(1-Drivers!$H$112) -> 84.75 | Q27: =P27+MIN(0,Q25)+Q26*Drivers!$H$110+P26*(Drivers!$H$111-Drivers!$H$110)+O26*(Drivers!$H$112-Drivers!$H$111)+N26*(1-Drivers!$H$112) -> 86 | R27: =Q27+MIN(0,R25)+R26*Drivers!$H$110+Q26*(Drivers!$H$111-Drivers!$H$110)+P26*(Drivers!$H$112-Drivers!$H$111)+O26*(1-Drivers!$H$112) -> 87.05 | S27: =R27+MIN(0,S25)+S26*Drivers!$H$110+R26*(Drivers!$H$111-Drivers!$H$110)+Q26*(Drivers!$H$112-Drivers!$H$111)+P26*(1-Drivers!$H$112) -> 88.05
B28: ="Volume per mature location ("&Inputs!$C$76&")" -> Volume per mature location (Customers ('000)) | C28: # | E28: =IF(E24=0,0,E30/E24) -> 3.3529412 | F28: =IF(F24=0,0,F30/F24) -> 3.0724638 | G28: =IF(G24=0,0,G30/G24) -> 3.1285714 | H28: =IF(H24=0,0,H30/H24) -> 3.3835616 | I28: =IF(I24=0,0,I30/I24) -> 3.4533333 | J28: =IF(J24=0,0,J30/J24) -> 3.5131579 | K28: =IF(K24=0,0,K30/K24) -> 3.5584416 | L28: =K28*(1+Drivers!L65) -> 3.594026 | M28: =L28*(1+Drivers!M65) -> 3.6263722 | N28: =M28*(1+Drivers!N65) -> 3.6553832 | O28: =N28*(1+Drivers!O65) -> 3.6809709 | P28: =O28*(1+Drivers!P65) -> 3.7030567 | Q28: =P28*(1+Drivers!Q65) -> 3.721572 | R28: =Q28*(1+Drivers!R65) -> 3.7364583 | S28: =R28*(1+Drivers!S65) -> 3.7476676
B29: Like-for-like growth | C29: % | F29: =IF(E28=0,0,F28/E28-1) -> -0.083651157 | G29: =IF(F28=0,0,G28/F28-1) -> 0.018261456 | H29: =IF(G28=0,0,H28/G28-1) -> 0.081503722 | I29: =IF(H28=0,0,I28/H28-1) -> 0.020620783 | J29: =IF(I28=0,0,J28/I28-1) -> 0.017323715 | K29: =IF(J28=0,0,K28/J28-1) -> 0.012889732 | L29: =IF(K28=0,0,L28/K28-1) -> 0.01 | M29: =IF(L28=0,0,M28/L28-1) -> 0.009 | ... S29: =IF(R28=0,0,S28/R28-1) -> 0.003
B30: ="Volume ("&Inputs!$C$76&")" -> Volume (Customers ('000)) | C30: # | E30: =Hist!E75 -> 228 | F30: =Hist!F75 -> 212 | G30: =Hist!G75 -> 219 | H30: =Hist!H75 -> 247 | I30: =Hist!I75 -> 259 | J30: =Hist!J75 -> 267 | K30: =Hist!K75 -> 274 | L30: =IF(Inputs!$C$72=2,L27*L28,K30*(1+Drivers!L60)) -> 279.25582 | M30: =IF(Inputs!$C$72=2,M27*M28,L30*(1+Drivers!M60)) -> 287.20868 | N30: =IF(Inputs!$C$72=2,N27*N28,M30*(1+Drivers!N60)) -> 296.45158 | O30: =IF(Inputs!$C$72=2,O27*O28,N30*(1+Drivers!O60)) -> 305.88868 | P30: =IF(Inputs!$C$72=2,P27*P28,O30*(1+Drivers!P60)) -> 313.83405 | Q30: =IF(Inputs!$C$72=2,Q27*Q28,P30*(1+Drivers!Q60)) -> 320.05519 | R30: =IF(Inputs!$C$72=2,R27*R28,Q30*(1+Drivers!R60)) -> 325.25869 | S30: =IF(Inputs!$C$72=2,S27*S28,R30*(1+Drivers!S60)) -> 329.98214
B31: Volume growth | C31: % | F31: =F30/E30-1 -> -0.070175439 | G31: =G30/F30-1 -> 0.033018868 | H31: =H30/G30-1 -> 0.12785388 | I31: =I30/H30-1 -> 0.048582996 | J31: =J30/I30-1 -> 0.030888031 | K31: =K30/J30-1 -> 0.026217228 | L31: =L30/K30-1 -> 0.019181818 | M31: =M30/L30-1 -> 0.028478764 | ... S31: =S30/R30-1 -> 0.014522114
B32: Revenue per unit | C32: NOK '000 | E32: =IF(E30=0,0,E34/E30) -> 5.4385965 | F32: =IF(F30=0,0,F34/F30) -> 5.3301887 | G32: =IF(G30=0,0,G34/G30) -> 5.43379 | H32: =IF(H30=0,0,H34/H30) -> 5.6680162 | I32: =IF(I30=0,0,I34/I30) -> 5.965251 | J32: =IF(J30=0,0,J34/J30) -> 6.2359551 | K32: =IF(K30=0,0,K34/K30) -> 6.5145985 | L32: =IF(L30=0,0,L34/L30) -> 6.7230657 | ... S32: =IF(S30=0,0,S34/S30) -> 8.0148501
B33: Price/mix growth | C33: % | F33: =(1+F35)/(1+F31)-1 -> -0.019933049 | G33: =(1+G35)/(1+G31)-1 -> 0.019436699 | H33: =(1+H35)/(1+H31)-1 -> 0.043105501 | I33: =(1+I35)/(1+I31)-1 -> 0.052440706 | J33: =(1+J35)/(1+J31)-1 -> 0.045380168 | K33: =(1+K35)/(1+K31)-1 -> 0.04468337 | L33: =(1+L35)/(1+L31)-1 -> 0.032 | M33: =(1+M35)/(1+M31)-1 -> 0.03 | ... S33: =(1+S35)/(1+S31)-1 -> 0.022
B34: Revenue | C34: NOKm | E34: =Hist!E10 -> 1240 | F34: =Hist!F10 -> 1130 | G34: =Hist!G10 -> 1190 | H34: =Hist!H10 -> 1400 | I34: =Hist!I10 -> 1545 | J34: =Hist!J10 -> 1665 | K34: =Hist!K10 -> 1785 | L34: =IF(K30=0,K34*(1+Drivers!L60),K34*L30/K30)*(1+Drivers!L61) -> 1877.4552 | M34: =IF(L30=0,L34*(1+Drivers!M60),L34*M30/L30)*(1+Drivers!M61) -> 1988.8505 | N34: =IF(M30=0,M34*(1+Drivers!N60),M34*N30/M30)*(1+Drivers!N61) -> 2110.3353 | O34: =IF(N30=0,N34*(1+Drivers!O60),N34*O30/N30)*(1+Drivers!O61) -> 2234.1301 | P34: =IF(O30=0,O34*(1+Drivers!P60),O34*P30/O30)*(1+Drivers!P61) -> 2349.465 | Q34: =IF(P30=0,P34*(1+Drivers!Q60),P34*Q30/P30)*(1+Drivers!Q61) -> 2453.5434 | R34: =IF(Q30=0,Q34*(1+Drivers!R60),Q34*R30/Q30)*(1+Drivers!R61) -> 2550.7825 | S34: =IF(R30=0,R34*(1+Drivers!S60),R34*S30/R30)*(1+Drivers!S61) -> 2644.7574
B35: Revenue growth | C35: % | F35: =F34/E34-1 -> -0.088709677 | G35: =G34/F34-1 -> 0.053097345 | H35: =H34/G34-1 -> 0.17647059 | I35: =I34/H34-1 -> 0.10357143 | J35: =J34/I34-1 -> 0.077669903 | K35: =K34/J34-1 -> 0.072072072 | L35: =L34/K34-1 -> 0.051795636 | M35: =M34/L34-1 -> 0.059333127 | ... S35: =S34/R34-1 -> 0.0368416
B37: =Inputs!$C$75 -> Denmark & Finland
B38: Locations (end of year) | C38: # | E38: =Hist!E79 -> 32 | F38: =Hist!F79 -> 32 | G38: =Hist!G79 -> 33 | H38: =Hist!H79 -> 40 | I38: =Hist!I79 -> 42 | J38: =Hist!J79 -> 44 | K38: =Hist!K79 -> 46 | L38: =K38+L39 -> 49 | M38: =L38+M39 -> 52 | N38: =M38+N39 -> 55 | O38: =N38+O39 -> 57 | P38: =O38+P39 -> 59 | Q38: =P38+Q39 -> 61 | R38: =Q38+R39 -> 62 | S38: =R38+S39 -> 63
B39: Net new locations | C39: # | F39: =F38-E38 -> 0 | G39: =G38-F38 -> 1 | H39: =H38-G38 -> 7 | I39: =I38-H38 -> 2 | J39: =J38-I38 -> 2 | K39: =K38-J38 -> 2 | L39: =Drivers!L69 -> 3 | M39: =Drivers!M69 -> 3 | N39: =Drivers!N69 -> 3 | O39: =Drivers!O69 -> 2 | P39: =Drivers!P69 -> 2 | Q39: =Drivers!Q69 -> 2 | R39: =Drivers!R69 -> 1 | S39: =Drivers!S69 -> 1
B40: Openings still ramping up (forecast openings only) | C40: # | E40: =0 -> 0 | F40: =0 -> 0 | G40: =0 -> 0 | H40: =0 -> 0 | I40: =0 -> 0 | J40: =0 -> 0 | K40: =0 -> 0 | L40: =MAX(0,L39) -> 3 | M40: =MAX(0,M39) -> 3 | N40: =MAX(0,N39) -> 3 | O40: =MAX(0,O39) -> 2 | P40: =MAX(0,P39) -> 2 | Q40: =MAX(0,Q39) -> 2 | R40: =MAX(0,R39) -> 1 | S40: =MAX(0,S39) -> 1
B41: Mature-equivalent locations | C41: # | E41: =E38 -> 32 | F41: =F38 -> 32 | G41: =G38 -> 33 | H41: =H38 -> 40 | I41: =I38 -> 42 | J41: =J38 -> 44 | K41: =K38 -> 46 | L41: =K41+MIN(0,L39)+L40*Drivers!$H$110+K40*(Drivers!$H$111-Drivers!$H$110)+J40*(Drivers!$H$112-Drivers!$H$111)+I40*(1-Drivers!$H$112) -> 47.05 | M41: =L41+MIN(0,M39)+M40*Drivers!$H$110+L40*(Drivers!$H$111-Drivers!$H$110)+K40*(Drivers!$H$112-Drivers!$H$111)+J40*(1-Drivers!$H$112) -> 49.3 | N41: =M41+MIN(0,N39)+N40*Drivers!$H$110+M40*(Drivers!$H$111-Drivers!$H$110)+L40*(Drivers!$H$112-Drivers!$H$111)+K40*(1-Drivers!$H$112) -> 52.15 | O41: =N41+MIN(0,O39)+O40*Drivers!$H$110+N40*(Drivers!$H$111-Drivers!$H$110)+M40*(Drivers!$H$112-Drivers!$H$111)+L40*(1-Drivers!$H$112) -> 54.8 | P41: =O41+MIN(0,P39)+P40*Drivers!$H$110+O40*(Drivers!$H$111-Drivers!$H$110)+N40*(Drivers!$H$112-Drivers!$H$111)+M40*(1-Drivers!$H$112) -> 57.05 | Q41: =P41+MIN(0,Q39)+Q40*Drivers!$H$110+P40*(Drivers!$H$111-Drivers!$H$110)+O40*(Drivers!$H$112-Drivers!$H$111)+N40*(1-Drivers!$H$112) -> 59.1 | R41: =Q41+MIN(0,R39)+R40*Drivers!$H$110+Q40*(Drivers!$H$111-Drivers!$H$110)+P40*(Drivers!$H$112-Drivers!$H$111)+O40*(1-Drivers!$H$112) -> 60.75 | S41: =R41+MIN(0,S39)+S40*Drivers!$H$110+R40*(Drivers!$H$111-Drivers!$H$110)+Q40*(Drivers!$H$112-Drivers!$H$111)+P40*(1-Drivers!$H$112) -> 62
B42: ="Volume per mature location ("&Inputs!$C$76&")" -> Volume per mature location (Customers ('000)) | C42: # | E42: =IF(E38=0,0,E44/E38) -> 3.6875 | F42: =IF(F38=0,0,F44/F38) -> 3.4375 | G42: =IF(G38=0,0,G44/G38) -> 3.5454545 | H42: =IF(H38=0,0,H44/H38) -> 3.3 | I42: =IF(I38=0,0,I44/I38) -> 3.4047619 | J42: =IF(J38=0,0,J44/J38) -> 3.4090909 | K42: =IF(K38=0,0,K44/K38) -> 3.4347826 | L42: =K42*(1+Drivers!L66) -> 3.4863043 | M42: =L42*(1+Drivers!M66) -> 3.5351126 | N42: =M42*(1+Drivers!N66) -> 3.577534 | O42: =N42*(1+Drivers!O66) -> 3.6133093 | P42: =O42*(1+Drivers!P66) -> 3.6458291 | Q42: =P42*(1+Drivers!Q66) -> 3.6749957 | R42: =Q42*(1+Drivers!R66) -> 3.6970457 | S42: =R42*(1+Drivers!S66) -> 3.7155309
B43: Like-for-like growth | C43: % | F43: =IF(E42=0,0,F42/E42-1) -> -0.06779661 | G43: =IF(F42=0,0,G42/F42-1) -> 0.031404959 | H43: =IF(G42=0,0,H42/G42-1) -> -0.069230769 | I43: =IF(H42=0,0,I42/H42-1) -> 0.031746032 | J43: =IF(I42=0,0,J42/I42-1) -> 0.0012714558 | K43: =IF(J42=0,0,K42/J42-1) -> 0.0075362319 | L43: =IF(K42=0,0,L42/K42-1) -> 0.015 | M43: =IF(L42=0,0,M42/L42-1) -> 0.014 | ... S43: =IF(R42=0,0,S42/R42-1) -> 0.005
B44: ="Volume ("&Inputs!$C$76&")" -> Volume (Customers ('000)) | C44: # | E44: =Hist!E76 -> 118 | F44: =Hist!F76 -> 110 | G44: =Hist!G76 -> 117 | H44: =Hist!H76 -> 132 | I44: =Hist!I76 -> 143 | J44: =Hist!J76 -> 150 | K44: =Hist!K76 -> 158 | L44: =IF(Inputs!$C$72=2,L41*L42,K44*(1+Drivers!L62)) -> 164.03062 | M44: =IF(Inputs!$C$72=2,M41*M42,L44*(1+Drivers!M62)) -> 174.28105 | N44: =IF(Inputs!$C$72=2,N41*N42,M44*(1+Drivers!N62)) -> 186.5684 | O44: =IF(Inputs!$C$72=2,O41*O42,N44*(1+Drivers!O62)) -> 198.00935 | P44: =IF(Inputs!$C$72=2,P41*P42,O44*(1+Drivers!P62)) -> 207.99455 | Q44: =IF(Inputs!$C$72=2,Q41*Q42,P44*(1+Drivers!Q62)) -> 217.19225 | R44: =IF(Inputs!$C$72=2,R41*R42,Q44*(1+Drivers!R62)) -> 224.59553 | S44: =IF(Inputs!$C$72=2,S41*S42,R44*(1+Drivers!S62)) -> 230.36292
...

Sheet Output >>>
D8: =Inputs!$C$6 -> Example Company ASA
D9: Financial Model
D12: Output
D14: Link-only presentation of the results – what you would show in a report.
D17: Output | E17: Financial statements | F17: Income statement, balance sheet (capital employed) and cash flow with integrity checks
D18: Analysis | E18: Financial analysis | F18: Growth, margins, ROIC vs. WACC, leverage, per-share data and valuation multiples
D21: ← Back to cover

Sheet Output
B1: Output Financial Statements | T1: =Inputs!$C$6&" | Scenario: "&Inputs!$C$53 -> Example Company ASA | Scenario: Base
B2: Link-only presentation of the income statement, balance sheet and cash flow – no assumptions are entered here.
E3: =Inputs!$C$17+0 -> 2019 | F3: =Inputs!$C$17+1 -> 2020 | G3: =Inputs!$C$17+2 -> 2021 | H3: =Inputs!$C$17+3 -> 2022 | I3: =Inputs!$C$17+4 -> 2023 | J3: =Inputs!$C$17+5 -> 2024 | K3: =Inputs!$C$17+6 -> 2025 | L3: =Inputs!$C$19+0 -> 2026 | M3: =Inputs!$C$19+1 -> 2027 | N3: =Inputs!$C$19+2 -> 2028 | O3: =Inputs!$C$19+3 -> 2029 | P3: =Inputs!$C$19+4 -> 2030 | Q3: =Inputs!$C$19+5 -> 2031 | R3: =Inputs!$C$19+6 -> 2032 | S3: =Inputs!$C$19+7 -> 2033
E4: Historicals | L4: Explicit forecast
B5: ="("&Inputs!$C$11&")" -> (NOKm) | E5: =E3&"A" -> 2019A | F5: =F3&"A" -> 2020A | G5: =G3&"A" -> 2021A | H5: =H3&"A" -> 2022A | I5: =I3&"A" -> 2023A | J5: =J3&"A" -> 2024A | K5: =K3&"A" -> 2025A | L5: =L3&"E" -> 2026E | M5: =M3&"E" -> 2027E | N5: =N3&"E" -> 2028E | O5: =O3&"E" -> 2029E | P5: =P3&"E" -> 2030E | Q5: =Q3&"E" -> 2031E | R5: =R3&"E" -> 2032E | S5: =S3&"E" -> 2033E | V5: Notes
B7: Income statement
B9: Revenue | C9: NOKm | E9: =Model!E67 -> 3790 | F9: =Model!F67 -> 3468 | G9: =Model!G67 -> 3668 | H9: =Model!H67 -> 4262 | I9: =Model!I67 -> 4687 | J9: =Model!J67 -> 5045 | K9: =Model!K67 -> 5433 | L9: =Model!L67 -> 5726.448 | ... S9: =Model!S67 -> 8244.1745
B10: Growth | C10: % | F10: =F9/E9-1 -> -0.084960422 | G10: =G9/F9-1 -> 0.057670127 | H10: =H9/G9-1 -> 0.16194111 | I10: =I9/H9-1 -> 0.099718442 | J10: =J9/I9-1 -> 0.076381481 | K10: =K9/J9-1 -> 0.07690783 | L10: =L9/K9-1 -> 0.05401214 | M10: =M9/L9-1 -> 0.062411248 | ... S10: =S9/R9-1 -> 0.038463123
B12: Cost of goods sold | C12: NOKm | E12: =Model!E68 -> -1383.3 | F12: =Model!F68 -> -1310.9 | G12: =Model!G68 -> -1364.5 | H12: =Model!H68 -> -1623.8 | I12: =Model!I68 -> -1762.3 | J12: =Model!J68 -> -1866.7 | K12: =Model!K68 -> -1988.5 | L12: =Model!L68 -> -2095.88 | ... S12: =Model!S68 -> -3017.3679
B13: Gross profit | C13: NOKm | E13: =Model!E69 -> 2406.7 | F13: =Model!F69 -> 2157.1 | G13: =Model!G69 -> 2303.5 | H13: =Model!H69 -> 2638.2 | I13: =Model!I69 -> 2924.7 | J13: =Model!J69 -> 3178.3 | K13: =Model!K69 -> 3444.5 | L13: =Model!L69 -> 3630.568 | ... S13: =Model!S69 -> 5226.8066
B14: Margin | C14: % | E14: =E13/E9 -> 0.63501319 | F14: =F13/F9 -> 0.62200115 | G14: =G13/G9 -> 0.62799891 | H14: =H13/H9 -> 0.61900516 | I14: =I13/I9 -> 0.62400256 | J14: =J13/J9 -> 0.62999009 | K14: =K13/K9 -> 0.63399595 | L14: =L13/L9 -> 0.634 | ... S14: =S13/S9 -> 0.634
B16: Personnel expenses | C16: NOKm | E16: =Model!E74 -> -871.7 | F16: =Model!F74 -> -853.1 | G16: =Model!G74 -> -873 | H16: =Model!H74 -> -976 | I16: =Model!I74 -> -1049.9 | J16: =Model!J74 -> -1114.9 | K16: =Model!K74 -> -1184.4 | L16: =Model!L74 -> -1247.9798 | ... S16: =Model!S74 -> -1720.8828
B17: Other operating expenses | C17: NOKm | E17: =Model!E77 -> -485.1 | F17: =Model!F77 -> -468.2 | G17: =Model!G77 -> -480.5 | H17: =Model!H77 -> -537 | I17: =Model!I77 -> -576.5 | J17: =Model!J77 -> -610.4 | K17: =Model!K77 -> -646.5 | L17: =Model!L77 -> -681.25582 | ... S17: =Model!S77 -> -946.30562
B18: EBITDA | C18: NOKm | E18: =Model!E78 -> 1049.9 | F18: =Model!F78 -> 835.8 | G18: =Model!G78 -> 950 | H18: =Model!H78 -> 1125.2 | I18: =Model!I78 -> 1298.3 | J18: =Model!J78 -> 1453 | K18: =Model!K78 -> 1613.6 | L18: =Model!L78 -> 1701.3324 | ... S18: =Model!S78 -> 2559.6182
B19: Margin | C19: % | E19: =E18/E9 -> 0.27701847 | F19: =F18/F9 -> 0.24100346 | G19: =G18/G9 -> 0.25899673 | H19: =H18/H9 -> 0.26400751 | I19: =I18/I9 -> 0.27700021 | J19: =J18/J9 -> 0.28800793 | K19: =K18/K9 -> 0.29699982 | L19: =L18/L9 -> 0.29710083 | ... S19: =S18/S9 -> 0.31047598
B21: D&A – owned assets | C21: NOKm | E21: =Model!E84 -> -174.3 | F21: =Model!F84 -> -176.9 | G21: =Model!G84 -> -179.7 | H21: =Model!H84 -> -196.1 | I21: =Model!I84 -> -210.9 | J21: =Model!J84 -> -227 | K21: =Model!K84 -> -239.1 | L21: =Model!L84 -> -251.96371 | ... S21: =Model!S84 -> -362.74368
B22: Depreciation – right-of-use assets | C22: NOKm | E22: =Model!E90 -> -254.7 | F22: =Model!F90 -> -258 | G22: =Model!G90 -> -261.2 | H22: =Model!H90 -> -279.6 | I22: =Model!I90 -> -300 | J22: =Model!J90 -> -318.9 | K22: =Model!K90 -> -339 | L22: =Model!L90 -> -359.81808 | ... S22: =Model!S90 -> -500.45526
B23: Impairments and special items | C23: NOKm | E23: =Model!E89 -> 0 | F23: =Model!F89 -> -45 | G23: =Model!G89 -> 0 | H23: =Model!H89 -> 0 | I23: =Model!I89 -> -20 | J23: =Model!J89 -> 0 | K23: =Model!K89 -> 0 | L23: =Model!L89 -> 0 | ... S23: =Model!S89 -> 0
B24: EBIT | C24: NOKm | E24: =Model!E91 -> 620.9 | F24: =Model!F91 -> 355.9 | G24: =Model!G91 -> 509.1 | H24: =Model!H91 -> 649.5 | I24: =Model!I91 -> 767.4 | J24: =Model!J91 -> 907.1 | K24: =Model!K91 -> 1035.5 | L24: =Model!L91 -> 1089.5506 | ... S24: =Model!S91 -> 1696.4192
